Workbook

Sheet Заказы
A1: Дата заказа: | B1: 46287 | C1: ← введите дату вручную, она подставится во все накладные
A2: Десерт/точка | B2: Арена Урбо | C2: Карсити | D2: Ашимова | E2: Гагарина | F2: Алапарк | G2: Аксай | H2: Сайран | I2: Арена Эксперт | J2: Навои | K2: Точка 10 | L2: Точка 11 | M2: Точка 12 | N2: Точка 13 | O2: Точка 14 | P2: Точка 15 | Q2: Точка 16 | R2: Точка 17 | S2: Точка 18 | T2: Точка 19 | U2: Точка 20 | V2: Точка 21 | W2: Точка 22 | X2: Точка 23 | Y2: Точка 24
A3: Вупи пай | B3: 6 | C3: 3 | F3: 6 | G3: 4 | J3: 2
A4: Фисташковый рулет | B4: 5 | D4: 2 | E4: 1 | F4: 6 | G4: 5
A5: Молочная девочка
A6: Медовик | B6: 6
A7: Испанский чизкейк
A8: Казакша чизкейк
A9: Картошка
A10: Шоколадный брауни
A11: Мини брауни
A12: Кукис Фисташка
A13: Кукис Брауни
A14: Кукис Красный Бархат
A15: Кукис Классика
A16: Брауни комплимент
A17: Тарт Клубника | B17: 1
A18: Тарт Малина
A19: Тарт Баноффи
A20: Круассан классика
A21: Круассан миндальный
A22: Круассан Фисташка
A23: Круассан с сыром
A24: Круассан со сгущенкой
A25: Круассан с шоколадом
A26: Круассан для сэндвичей
A27: Мак булочка
A28: Сырники
A29: Гранола
A31: Вводите только количество в ячейки. Пусто = заказа нет. Цены и итоги считаются автоматически.

Sheet Каталог
A1: Наименование | B1: Ед. | C1: Цена | D1: Примечание
A2: Вупи пай | B2: Шт | C2: 690
A3: Фисташковый рулет | B3: Шт | C3: 890
A4: Молочная девочка | B4: Шт | C4: 590
A5: Медовик | B5: Шт | C5: 590
A6: Испанский чизкейк | B6: Шт | C6: 690
A7: Казакша чизкейк | B7: Шт | C7: 790
A8: Картошка | B8: Шт | C8: 590
A9: Шоколадный брауни | B9: Шт | C9: 750
A10: Мини брауни | B10: Шт | C10: 890
A11: Кукис Фисташка | B11: Шт | C11: 500
A12: Кукис Брауни | B12: Шт | C12: 500
A13: Кукис Красный Бархат | B13: Шт | C13: 500
A14: Кукис Классика | B14: Шт | C14: 500
A15: Брауни комплимент | B15: Порция | D15: Цена не указана
A16: Тарт Клубника | B16: Шт | C16: 400
A17: Тарт Малина | B17: Шт | C17: 400
A18: Тарт Баноффи | B18: Шт | C18: 400
A19: Круассан классика | B19: Шт | C19: 590
A20: Круассан миндальный | B20: Шт | C20: 920
A21: Круассан Фисташка | B21: Шт | C21: 850
A22: Круассан с сыром | B22: Шт | C22: 890
A23: Круассан со сгущенкой | B23: Шт | C23: 650
A24: Круассан с шоколадом | B24: Шт | C24: 650
A25: Круассан для сэндвичей | B25: Шт | C25: 590
A26: Мак булочка | B26: Шт | C26: 200
A27: Сырники | B27: Коробка | C27: 16000 | D27: 50 шт в коробке
A28: Гранола | B28: Упаковка | C28: 2000 | D28: 250 гр в упаковке

Sheet Итоги
A1: Кофейня | B1: Количество позиций | C1: Общая сумма
A2: Арена Урбо | B2: =COUNTIF(Заказы!$B$3:$B$29,">0") -> 4 | C2: =SUMPRODUCT(Заказы!$B$3:$B$29,Каталог!$C$2:$C$28) -> 12530
A3: Карсити | B3: =COUNTIF(Заказы!$C$3:$C$29,">0") -> 1 | C3: =SUMPRODUCT(Заказы!$C$3:$C$29,Каталог!$C$2:$C$28) -> 2070
A4: Ашимова | B4: =COUNTIF(Заказы!$D$3:$D$29,">0") -> 1 | C4: =SUMPRODUCT(Заказы!$D$3:$D$29,Каталог!$C$2:$C$28) -> 1780
A5: Гагарина | B5: =COUNTIF(Заказы!$E$3:$E$29,">0") -> 1 | C5: =SUMPRODUCT(Заказы!$E$3:$E$29,Каталог!$C$2:$C$28) -> 890
A6: Алапарк | B6: =COUNTIF(Заказы!$F$3:$F$29,">0") -> 2 | C6: =SUMPRODUCT(Заказы!$F$3:$F$29,Каталог!$C$2:$C$28) -> 9480
A7: Аксай | B7: =COUNTIF(Заказы!$G$3:$G$29,">0") -> 2 | C7: =SUMPRODUCT(Заказы!$G$3:$G$29,Каталог!$C$2:$C$28) -> 7210
A8: Сайран | B8: =COUNTIF(Заказы!$H$3:$H$29,">0") -> 0 | C8: =SUMPRODUCT(Заказы!$H$3:$H$29,Каталог!$C$2:$C$28) -> 0
A9: Арена Эксперт | B9: =COUNTIF(Заказы!$I$3:$I$29,">0") -> 0 | C9: =SUMPRODUCT(Заказы!$I$3:$I$29,Каталог!$C$2:$C$28) -> 0
A10: Навои | B10: =COUNTIF(Заказы!$J$3:$J$29,">0") -> 1 | C10: =SUMPRODUCT(Заказы!$J$3:$J$29,Каталог!$C$2:$C$28) -> 1380
A11: Точка 10 | B11: =COUNTIF(Заказы!$K$3:$K$29,">0") -> 0 | C11: =SUMPRODUCT(Заказы!$K$3:$K$29,Каталог!$C$2:$C$28) -> 0
A12: Точка 11 | B12: =COUNTIF(Заказы!$L$3:$L$29,">0") -> 0 | C12: =SUMPRODUCT(Заказы!$L$3:$L$29,Каталог!$C$2:$C$28) -> 0
A13: Точка 12 | B13: =COUNTIF(Заказы!$M$3:$M$29,">0") -> 0 | C13: =SUMPRODUCT(Заказы!$M$3:$M$29,Каталог!$C$2:$C$28) -> 0
A14: Точка 13 | B14: =COUNTIF(Заказы!$N$3:$N$29,">0") -> 0 | C14: =SUMPRODUCT(Заказы!$N$3:$N$29,Каталог!$C$2:$C$28) -> 0
A15: Точка 14 | B15: =COUNTIF(Заказы!$O$3:$O$29,">0") -> 0 | C15: =SUMPRODUCT(Заказы!$O$3:$O$29,Каталог!$C$2:$C$28) -> 0
A16: Точка 15 | B16: =COUNTIF(Заказы!$P$3:$P$29,">0") -> 0 | C16: =SUMPRODUCT(Заказы!$P$3:$P$29,Каталог!$C$2:$C$28) -> 0
A17: Точка 16 | B17: =COUNTIF(Заказы!$Q$3:$Q$29,">0") -> 0 | C17: =SUMPRODUCT(Заказы!$Q$3:$Q$29,Каталог!$C$2:$C$28) -> 0
A18: Точка 17 | B18: =COUNTIF(Заказы!$R$3:$R$29,">0") -> 0 | C18: =SUMPRODUCT(Заказы!$R$3:$R$29,Каталог!$C$2:$C$28) -> 0
A19: Точка 18 | B19: =COUNTIF(Заказы!$S$3:$S$29,">0") -> 0 | C19: =SUMPRODUCT(Заказы!$S$3:$S$29,Каталог!$C$2:$C$28) -> 0
A20: Точка 19 | B20: =COUNTIF(Заказы!$T$3:$T$29,">0") -> 0 | C20: =SUMPRODUCT(Заказы!$T$3:$T$29,Каталог!$C$2:$C$28) -> 0
A21: Точка 20 | B21: =COUNTIF(Заказы!$U$3:$U$29,">0") -> 0 | C21: =SUMPRODUCT(Заказы!$U$3:$U$29,Каталог!$C$2:$C$28) -> 0
A22: Точка 21 | B22: =COUNTIF(Заказы!$V$3:$V$29,">0") -> 0 | C22: =SUMPRODUCT(Заказы!$V$3:$V$29,Каталог!$C$2:$C$28) -> 0
A23: Точка 22 | B23: =COUNTIF(Заказы!$W$3:$W$29,">0") -> 0 | C23: =SUMPRODUCT(Заказы!$W$3:$W$29,Каталог!$C$2:$C$28) -> 0
A24: Точка 23 | B24: =COUNTIF(Заказы!$X$3:$X$29,">0") -> 0 | C24: =SUMPRODUCT(Заказы!$X$3:$X$29,Каталог!$C$2:$C$28) -> 0
A25: Точка 24 | B25: =COUNTIF(Заказы!$Y$3:$Y$29,">0") -> 0 | C25: =SUMPRODUCT(Заказы!$Y$3:$Y$29,Каталог!$C$2:$C$28) -> 0
A26: ИТОГО | B26: =SUM(B2:B25) -> 12 | C26: =SUM(C2:C25) -> 35340
A29: Товар | B29: Кол-во заказано | C29: Сумма
A30: =Заказы!$A$3 -> Вупи пай | B30: =SUM(Заказы!$B$3:$Y$3) -> 21 | C30: =B30*Каталог!$C$2 -> 14490
A31: =Заказы!$A$4 -> Фисташковый рулет | B31: =SUM(Заказы!$B$4:$Y$4) -> 19 | C31: =B31*Каталог!$C$3 -> 16910
A32: =Заказы!$A$5 -> Молочная девочка | B32: =SUM(Заказы!$B$5:$Y$5) -> 0 | C32: =B32*Каталог!$C$4 -> 0
A33: =Заказы!$A$6 -> Медовик | B33: =SUM(Заказы!$B$6:$Y$6) -> 6 | C33: =B33*Каталог!$C$5 -> 3540
A34: =Заказы!$A$7 -> Испанский чизкейк | B34: =SUM(Заказы!$B$7:$Y$7) -> 0 | C34: =B34*Каталог!$C$6 -> 0
A35: =Заказы!$A$8 -> Казакша чизкейк | B35: =SUM(Заказы!$B$8:$Y$8) -> 0 | C35: =B35*Каталог!$C$7 -> 0
A36: =Заказы!$A$9 -> Картошка | B36: =SUM(Заказы!$B$9:$Y$9) -> 0 | C36: =B36*Каталог!$C$8 -> 0
A37: =Заказы!$A$10 -> Шоколадный брауни | B37: =SUM(Заказы!$B$10:$Y$10) -> 0 | C37: =B37*Каталог!$C$9 -> 0
A38: =Заказы!$A$11 -> Мини брауни | B38: =SUM(Заказы!$B$11:$Y$11) -> 0 | C38: =B38*Каталог!$C$10 -> 0
A39: =Заказы!$A$12 -> Кукис Фисташка | B39: =SUM(Заказы!$B$12:$Y$12) -> 0 | C39: =B39*Каталог!$C$11 -> 0
A40: =Заказы!$A$13 -> Кукис Брауни | B40: =SUM(Заказы!$B$13:$Y$13) -> 0 | C40: =B40*Каталог!$C$12 -> 0
A41: =Заказы!$A$14 -> Кукис Красный Бархат | B41: =SUM(Заказы!$B$14:$Y$14) -> 0 | C41: =B41*Каталог!$C$13 -> 0
A42: =Заказы!$A$15 -> Кукис Классика | B42: =SUM(Заказы!$B$15:$Y$15) -> 0 | C42: =B42*Каталог!$C$14 -> 0
...

Sheet Накладные
A2: =IF(COUNTIF(Заказы!$B$3:$B$29,">0")=0,"","НАКЛАДНАЯ") -> НАКЛАДНАЯ | H2: =IF(COUNTIF(Заказы!$C$3:$C$29,">0")=0,"","НАКЛАДНАЯ") -> НАКЛАДНАЯ
A3: =IF(COUNTIF(Заказы!$B$3:$B$29,">0")=0,"","Отправитель: Brown кондитерский цех") -> Отправитель: Brown кондитерский цех | H3: =IF(COUNTIF(Заказы!$C$3:$C$29,">0")=0,"","Отправитель: Brown кондитерский цех") -> Отправитель: Brown кондитерский цех
A4: =IF(COUNTIF(Заказы!$B$3:$B$29,">0")=0,"","Получатель: "&Заказы!B$2) -> Получатель: Арена Урбо | H4: =IF(COUNTIF(Заказы!$C$3:$C$29,">0")=0,"","Получатель: "&Заказы!C$2) -> Получатель: Карсити
A5: =IF(COUNTIF(Заказы!$B$3:$B$29,">0")=0,"","Накладная от: "&TEXT(Заказы!$B$1,"dd.mm.yyyy")) -> Накладная от: 22.09.2026 | H5: =IF(COUNTIF(Заказы!$C$3:$C$29,">0")=0,"","Накладная от: "&TEXT(Заказы!$B$1,"dd.mm.yyyy")) -> Накладная от: 22.09.2026
A7: =IF(COUNTIF(Заказы!$B$3:$B$29,">0")=0,"","№") -> № | B7: =IF(COUNTIF(Заказы!$B$3:$B$29,">0")=0,"","Наименование") -> Наименование | C7: =IF(COUNTIF(Заказы!$B$3:$B$29,">0")=0,"","Кол.") -> Кол. | D7: =IF(COUNTIF(Заказы!$B$3:$B$29,">0")=0,"","Ед.") -> Ед. | E7: =IF(COUNTIF(Заказы!$B$3:$B$29,">0")=0,"","Цена") -> Цена | F7: =IF(COUNTIF(Заказы!$B$3:$B$29,">0")=0,"","Сумма") -> Сумма | H7: =IF(COUNTIF(Заказы!$C$3:$C$29,">0")=0,"","№") -> № | I7: =IF(COUNTIF(Заказы!$C$3:$C$29,">0")=0,"","Наименование") -> Наименование | J7: =IF(COUNTIF(Заказы!$C$3:$C$29,">0")=0,"","Кол.") -> Кол. | K7: =IF(COUNTIF(Заказы!$C$3:$C$29,">0")=0,"","Ед.") -> Ед. | L7: =IF(COUNTIF(Заказы!$C$3:$C$29,">0")=0,"","Цена") -> Цена | M7: =IF(COUNTIF(Заказы!$C$3:$C$29,">0")=0,"","Сумма") -> Сумма
A8: =IF(B8="","",1) -> 1 | B8: {=IFERROR(INDEX(Заказы!$A$3:$A$29,SMALL(IF(Заказы!$B$3:$B$29>0,ROW(Заказы!$B$3:$B$29)-ROW(B$3)+1),1)),"")} -> Вупи пай | C8: =IF(B8="","",INDEX(Заказы!$B$3:$B$29,MATCH(B8,Заказы!$A$3:$A$29,0))) -> 6 | D8: =IF(B8="","",VLOOKUP(B8,Каталог!$A:$C,2,0)) -> Шт | E8: =IF(B8="","",VLOOKUP(B8,Каталог!$A:$C,3,0)) -> 690 | F8: =IF(B8="","",C8*E8) -> 4140 | H8: =IF(I8="","",1) -> 1 | I8: {=IFERROR(INDEX(Заказы!$A$3:$A$29,SMALL(IF(Заказы!$C$3:$C$29>0,ROW(Заказы!$C$3:$C$29)-ROW(C$3)+1),1)),"")} -> Вупи пай | J8: =IF(I8="","",INDEX(Заказы!$C$3:$C$29,MATCH(I8,Заказы!$A$3:$A$29,0))) -> 3 | K8: =IF(I8="","",VLOOKUP(I8,Каталог!$A:$C,2,0)) -> Шт | L8: =IF(I8="","",VLOOKUP(I8,Каталог!$A:$C,3,0)) -> 690 | M8: =IF(I8="","",J8*L8) -> 2070
A9: =IF(B9="","",2) -> 2 | B9: {=IFERROR(INDEX(Заказы!$A$3:$A$29,SMALL(IF(Заказы!$B$3:$B$29>0,ROW(Заказы!$B$3:$B$29)-ROW(B$3)+1),2)),"")} -> Фисташковый рулет | C9: =IF(B9="","",INDEX(Заказы!$B$3:$B$29,MATCH(B9,Заказы!$A$3:$A$29,0))) -> 5 | D9: =IF(B9="","",VLOOKUP(B9,Каталог!$A:$C,2,0)) -> Шт | E9: =IF(B9="","",VLOOKUP(B9,Каталог!$A:$C,3,0)) -> 890 | F9: =IF(B9="","",C9*E9) -> 4450 | H9: =IF(I9="","",2) | I9: {=IFERROR(INDEX(Заказы!$A$3:$A$29,SMALL(IF(Заказы!$C$3:$C$29>0,ROW(Заказы!$C$3:$C$29)-ROW(C$3)+1),2)),"")} | J9: =IF(I9="","",INDEX(Заказы!$C$3:$C$29,MATCH(I9,Заказы!$A$3:$A$29,0))) | K9: =IF(I9="","",VLOOKUP(I9,Каталог!$A:$C,2,0)) | L9: =IF(I9="","",VLOOKUP(I9,Каталог!$A:$C,3,0)) | M9: =IF(I9="","",J9*L9)
A10: =IF(B10="","",3) -> 3 | B10: {=IFERROR(INDEX(Заказы!$A$3:$A$29,SMALL(IF(Заказы!$B$3:$B$29>0,ROW(Заказы!$B$3:$B$29)-ROW(B$3)+1),3)),"")} -> Медовик | C10: =IF(B10="","",INDEX(Заказы!$B$3:$B$29,MATCH(B10,Заказы!$A$3:$A$29,0))) -> 6 | D10: =IF(B10="","",VLOOKUP(B10,Каталог!$A:$C,2,0)) -> Шт | E10: =IF(B10="","",VLOOKUP(B10,Каталог!$A:$C,3,0)) -> 590 | F10: =IF(B10="","",C10*E10) -> 3540 | H10: =IF(I10="","",3) | I10: {=IFERROR(INDEX(Заказы!$A$3:$A$29,SMALL(IF(Заказы!$C$3:$C$29>0,ROW(Заказы!$C$3:$C$29)-ROW(C$3)+1),3)),"")} | J10: =IF(I10="","",INDEX(Заказы!$C$3:$C$29,MATCH(I10,Заказы!$A$3:$A$29,0))) | K10: =IF(I10="","",VLOOKUP(I10,Каталог!$A:$C,2,0)) | L10: =IF(I10="","",VLOOKUP(I10,Каталог!$A:$C,3,0)) | M10: =IF(I10="","",J10*L10)
A11: =IF(B11="","",4) -> 4 | B11: {=IFERROR(INDEX(Заказы!$A$3:$A$29,SMALL(IF(Заказы!$B$3:$B$29>0,ROW(Заказы!$B$3:$B$29)-ROW(B$3)+1),4)),"")} -> Тарт Клубника | C11: =IF(B11="","",INDEX(Заказы!$B$3:$B$29,MATCH(B11,Заказы!$A$3:$A$29,0))) -> 1 | D11: =IF(B11="","",VLOOKUP(B11,Каталог!$A:$C,2,0)) -> Шт | E11: =IF(B11="","",VLOOKUP(B11,Каталог!$A:$C,3,0)) -> 400 | F11: =IF(B11="","",C11*E11) -> 400 | H11: =IF(I11="","",4) | I11: {=IFERROR(INDEX(Заказы!$A$3:$A$29,SMALL(IF(Заказы!$C$3:$C$29>0,ROW(Заказы!$C$3:$C$29)-ROW(C$3)+1),4)),"")} | J11: =IF(I11="","",INDEX(Заказы!$C$3:$C$29,MATCH(I11,Заказы!$A$3:$A$29,0))) | K11: =IF(I11="","",VLOOKUP(I11,Каталог!$A:$C,2,0)) | L11: =IF(I11="","",VLOOKUP(I11,Каталог!$A:$C,3,0)) | M11: =IF(I11="","",J11*L11)
A12: =IF(B12="","",5) | B12: {=IFERROR(INDEX(Заказы!$A$3:$A$29,SMALL(IF(Заказы!$B$3:$B$29>0,ROW(Заказы!$B$3:$B$29)-ROW(B$3)+1),5)),"")} | C12: =IF(B12="","",INDEX(Заказы!$B$3:$B$29,MATCH(B12,Заказы!$A$3:$A$29,0))) | D12: =IF(B12="","",VLOOKUP(B12,Каталог!$A:$C,2,0)) | E12: =IF(B12="","",VLOOKUP(B12,Каталог!$A:$C,3,0)) | F12: =IF(B12="","",C12*E12) | H12: =IF(I12="","",5) | I12: {=IFERROR(INDEX(Заказы!$A$3:$A$29,SMALL(IF(Заказы!$C$3:$C$29>0,ROW(Заказы!$C$3:$C$29)-ROW(C$3)+1),5)),"")} | J12: =IF(I12="","",INDEX(Заказы!$C$3:$C$29,MATCH(I12,Заказы!$A$3:$A$29,0))) | K12: =IF(I12="","",VLOOKUP(I12,Каталог!$A:$C,2,0)) | L12: =IF(I12="","",VLOOKUP(I12,Каталог!$A:$C,3,0)) | M12: =IF(I12="","",J12*L12)
A13: =IF(B13="","",6) | B13: {=IFERROR(INDEX(Заказы!$A$3:$A$29,SMALL(IF(Заказы!$B$3:$B$29>0,ROW(Заказы!$B$3:$B$29)-ROW(B$3)+1),6)),"")} | C13: =IF(B13="","",INDEX(Заказы!$B$3:$B$29,MATCH(B13,Заказы!$A$3:$A$29,0))) | D13: =IF(B13="","",VLOOKUP(B13,Каталог!$A:$C,2,0)) | E13: =IF(B13="","",VLOOKUP(B13,Каталог!$A:$C,3,0)) | F13: =IF(B13="","",C13*E13) | H13: =IF(I13="","",6) | I13: {=IFERROR(INDEX(Заказы!$A$3:$A$29,SMALL(IF(Заказы!$C$3:$C$29>0,ROW(Заказы!$C$3:$C$29)-ROW(C$3)+1),6)),"")} | J13: =IF(I13="","",INDEX(Заказы!$C$3:$C$29,MATCH(I13,Заказы!$A$3:$A$29,0))) | K13: =IF(I13="","",VLOOKUP(I13,Каталог!$A:$C,2,0)) | L13: =IF(I13="","",VLOOKUP(I13,Каталог!$A:$C,3,0)) | M13: =IF(I13="","",J13*L13)
A14: =IF(B14="","",7) | B14: {=IFERROR(INDEX(Заказы!$A$3:$A$29,SMALL(IF(Заказы!$B$3:$B$29>0,ROW(Заказы!$B$3:$B$29)-ROW(B$3)+1),7)),"")} | C14: =IF(B14="","",INDEX(Заказы!$B$3:$B$29,MATCH(B14,Заказы!$A$3:$A$29,0))) | D14: =IF(B14="","",VLOOKUP(B14,Каталог!$A:$C,2,0)) | E14: =IF(B14="","",VLOOKUP(B14,Каталог!$A:$C,3,0)) | F14: =IF(B14="","",C14*E14) | H14: =IF(I14="","",7) | I14: {=IFERROR(INDEX(Заказы!$A$3:$A$29,SMALL(IF(Заказы!$C$3:$C$29>0,ROW(Заказы!$C$3:$C$29)-ROW(C$3)+1),7)),"")} | J14: =IF(I14="","",INDEX(Заказы!$C$3:$C$29,MATCH(I14,Заказы!$A$3:$A$29,0))) | K14: =IF(I14="","",VLOOKUP(I14,Каталог!$A:$C,2,0)) | L14: =IF(I14="","",VLOOKUP(I14,Каталог!$A:$C,3,0)) | M14: =IF(I14="","",J14*L14)
A15: =IF(B15="","",8) | B15: {=IFERROR(INDEX(Заказы!$A$3:$A$29,SMALL(IF(Заказы!$B$3:$B$29>0,ROW(Заказы!$B$3:$B$29)-ROW(B$3)+1),8)),"")} | C15: =IF(B15="","",INDEX(Заказы!$B$3:$B$29,MATCH(B15,Заказы!$A$3:$A$29,0))) | D15: =IF(B15="","",VLOOKUP(B15,Каталог!$A:$C,2,0)) | E15: =IF(B15="","",VLOOKUP(B15,Каталог!$A:$C,3,0)) | F15: =IF(B15="","",C15*E15) | H15: =IF(I15="","",8) | I15: {=IFERROR(INDEX(Заказы!$A$3:$A$29,SMALL(IF(Заказы!$C$3:$C$29>0,ROW(Заказы!$C$3:$C$29)-ROW(C$3)+1),8)),"")} | J15: =IF(I15="","",INDEX(Заказы!$C$3:$C$29,MATCH(I15,Заказы!$A$3:$A$29,0))) | K15: =IF(I15="","",VLOOKUP(I15,Каталог!$A:$C,2,0)) | L15: =IF(I15="","",VLOOKUP(I15,Каталог!$A:$C,3,0)) | M15: =IF(I15="","",J15*L15)
A16: =IF(B16="","",9) | B16: {=IFERROR(INDEX(Заказы!$A$3:$A$29,SMALL(IF(Заказы!$B$3:$B$29>0,ROW(Заказы!$B$3:$B$29)-ROW(B$3)+1),9)),"")} | C16: =IF(B16="","",INDEX(Заказы!$B$3:$B$29,MATCH(B16,Заказы!$A$3:$A$29,0))) | D16: =IF(B16="","",VLOOKUP(B16,Каталог!$A:$C,2,0)) | E16: =IF(B16="","",VLOOKUP(B16,Каталог!$A:$C,3,0)) | F16: =IF(B16="","",C16*E16) | H16: =IF(I16="","",9) | I16: {=IFERROR(INDEX(Заказы!$A$3:$A$29,SMALL(IF(Заказы!$C$3:$C$29>0,ROW(Заказы!$C$3:$C$29)-ROW(C$3)+1),9)),"")} | J16: =IF(I16="","",INDEX(Заказы!$C$3:$C$29,MATCH(I16,Заказы!$A$3:$A$29,0))) | K16: =IF(I16="","",VLOOKUP(I16,Каталог!$A:$C,2,0)) | L16: =IF(I16="","",VLOOKUP(I16,Каталог!$A:$C,3,0)) | M16: =IF(I16="","",J16*L16)
A17: =IF(B17="","",10) | B17: {=IFERROR(INDEX(Заказы!$A$3:$A$29,SMALL(IF(Заказы!$B$3:$B$29>0,ROW(Заказы!$B$3:$B$29)-ROW(B$3)+1),10)),"")} | C17: =IF(B17="","",INDEX(Заказы!$B$3:$B$29,MATCH(B17,Заказы!$A$3:$A$29,0))) | D17: =IF(B17="","",VLOOKUP(B17,Каталог!$A:$C,2,0)) | E17: =IF(B17="","",VLOOKUP(B17,Каталог!$A:$C,3,0)) | F17: =IF(B17="","",C17*E17) | H17: =IF(I17="","",10) | I17: {=IFERROR(INDEX(Заказы!$A$3:$A$29,SMALL(IF(Заказы!$C$3:$C$29>0,ROW(Заказы!$C$3:$C$29)-ROW(C$3)+1),10)),"")} | J17: =IF(I17="","",INDEX(Заказы!$C$3:$C$29,MATCH(I17,Заказы!$A$3:$A$29,0))) | K17: =IF(I17="","",VLOOKUP(I17,Каталог!$A:$C,2,0)) | L17: =IF(I17="","",VLOOKUP(I17,Каталог!$A:$C,3,0)) | M17: =IF(I17="","",J17*L17)
A18: =IF(B18="","",11) | B18: {=IFERROR(INDEX(Заказы!$A$3:$A$29,SMALL(IF(Заказы!$B$3:$B$29>0,ROW(Заказы!$B$3:$B$29)-ROW(B$3)+1),11)),"")} | C18: =IF(B18="","",INDEX(Заказы!$B$3:$B$29,MATCH(B18,Заказы!$A$3:$A$29,0))) | D18: =IF(B18="","",VLOOKUP(B18,Каталог!$A:$C,2,0)) | E18: =IF(B18="","",VLOOKUP(B18,Каталог!$A:$C,3,0)) | F18: =IF(B18="","",C18*E18) | H18: =IF(I18="","",11) | I18: {=IFERROR(INDEX(Заказы!$A$3:$A$29,SMALL(IF(Заказы!$C$3:$C$29>0,ROW(Заказы!$C$3:$C$29)-ROW(C$3)+1),11)),"")} | J18: =IF(I18="","",INDEX(Заказы!$C$3:$C$29,MATCH(I18,Заказы!$A$3:$A$29,0))) | K18: =IF(I18="","",VLOOKUP(I18,Каталог!$A:$C,2,0)) | L18: =IF(I18="","",VLOOKUP(I18,Каталог!$A:$C,3,0)) | M18: =IF(I18="","",J18*L18)
A19: =IF(B19="","",12) | B19: {=IFERROR(INDEX(Заказы!$A$3:$A$29,SMALL(IF(Заказы!$B$3:$B$29>0,ROW(Заказы!$B$3:$B$29)-ROW(B$3)+1),12)),"")} | C19: =IF(B19="","",INDEX(Заказы!$B$3:$B$29,MATCH(B19,Заказы!$A$3:$A$29,0))) | D19: =IF(B19="","",VLOOKUP(B19,Каталог!$A:$C,2,0)) | E19: =IF(B19="","",VLOOKUP(B19,Каталог!$A:$C,3,0)) | F19: =IF(B19="","",C19*E19) | H19: =IF(I19="","",12) | I19: {=IFERROR(INDEX(Заказы!$A$3:$A$29,SMALL(IF(Заказы!$C$3:$C$29>0,ROW(Заказы!$C$3:$C$29)-ROW(C$3)+1),12)),"")} | J19: =IF(I19="","",INDEX(Заказы!$C$3:$C$29,MATCH(I19,Заказы!$A$3:$A$29,0))) | K19: =IF(I19="","",VLOOKUP(I19,Каталог!$A:$C,2,0)) | L19: =IF(I19="","",VLOOKUP(I19,Каталог!$A:$C,3,0)) | M19: =IF(I19="","",J19*L19)
A20: =IF(B20="","",13) | B20: {=IFERROR(INDEX(Заказы!$A$3:$A$29,SMALL(IF(Заказы!$B$3:$B$29>0,ROW(Заказы!$B$3:$B$29)-ROW(B$3)+1),13)),"")} | C20: =IF(B20="","",INDEX(Заказы!$B$3:$B$29,MATCH(B20,Заказы!$A$3:$A$29,0))) | D20: =IF(B20="","",VLOOKUP(B20,Каталог!$A:$C,2,0)) | E20: =IF(B20="","",VLOOKUP(B20,Каталог!$A:$C,3,0)) | F20: =IF(B20="","",C20*E20) | H20: =IF(I20="","",13) | I20: {=IFERROR(INDEX(Заказы!$A$3:$A$29,SMALL(IF(Заказы!$C$3:$C$29>0,ROW(Заказы!$C$3:$C$29)-ROW(C$3)+1),13)),"")} | J20: =IF(I20="","",INDEX(Заказы!$C$3:$C$29,MATCH(I20,Заказы!$A$3:$A$29,0))) | K20: =IF(I20="","",VLOOKUP(I20,Каталог!$A:$C,2,0)) | L20: =IF(I20="","",VLOOKUP(I20,Каталог!$A:$C,3,0)) | M20: =IF(I20="","",J20*L20)
A21: =IF(B21="","",14) | B21: {=IFERROR(INDEX(Заказы!$A$3:$A$29,SMALL(IF(Заказы!$B$3:$B$29>0,ROW(Заказы!$B$3:$B$29)-ROW(B$3)+1),14)),"")} | C21: =IF(B21="","",INDEX(Заказы!$B$3:$B$29,MATCH(B21,Заказы!$A$3:$A$29,0))) | D21: =IF(B21="","",VLOOKUP(B21,Каталог!$A:$C,2,0)) | E21: =IF(B21="","",VLOOKUP(B21,Каталог!$A:$C,3,0)) | F21: =IF(B21="","",C21*E21) | H21: =IF(I21="","",14) | I21: {=IFERROR(INDEX(Заказы!$A$3:$A$29,SMALL(IF(Заказы!$C$3:$C$29>0,ROW(Заказы!$C$3:$C$29)-ROW(C$3)+1),14)),"")} | J21: =IF(I21="","",INDEX(Заказы!$C$3:$C$29,MATCH(I21,Заказы!$A$3:$A$29,0))) | K21: =IF(I21="","",VLOOKUP(I21,Каталог!$A:$C,2,0)) | L21: =IF(I21="","",VLOOKUP(I21,Каталог!$A:$C,3,0)) | M21: =IF(I21="","",J21*L21)
A22: =IF(B22="","",15) | B22: {=IFERROR(INDEX(Заказы!$A$3:$A$29,SMALL(IF(Заказы!$B$3:$B$29>0,ROW(Заказы!$B$3:$B$29)-ROW(B$3)+1),15)),"")} | C22: =IF(B22="","",INDEX(Заказы!$B$3:$B$29,MATCH(B22,Заказы!$A$3:$A$29,0))) | D22: =IF(B22="","",VLOOKUP(B22,Каталог!$A:$C,2,0)) | E22: =IF(B22="","",VLOOKUP(B22,Каталог!$A:$C,3,0)) | F22: =IF(B22="","",C22*E22) | H22: =IF(I22="","",15) | I22: {=IFERROR(INDEX(Заказы!$A$3:$A$29,SMALL(IF(Заказы!$C$3:$C$29>0,ROW(Заказы!$C$3:$C$29)-ROW(C$3)+1),15)),"")} | J22: =IF(I22="","",INDEX(Заказы!$C$3:$C$29,MATCH(I22,Заказы!$A$3:$A$29,0))) | K22: =IF(I22="","",VLOOKUP(I22,Каталог!$A:$C,2,0)) | L22: =IF(I22="","",VLOOKUP(I22,Каталог!$A:$C,3,0)) | M22: =IF(I22="","",J22*L22)
A23: =IF(B23="","",16) | B23: {=IFERROR(INDEX(Заказы!$A$3:$A$29,SMALL(IF(Заказы!$B$3:$B$29>0,ROW(Заказы!$B$3:$B$29)-ROW(B$3)+1),16)),"")} | C23: =IF(B23="","",INDEX(Заказы!$B$3:$B$29,MATCH(B23,Заказы!$A$3:$A$29,0))) | D23: =IF(B23="","",VLOOKUP(B23,Каталог!$A:$C,2,0)) | E23: =IF(B23="","",VLOOKUP(B23,Каталог!$A:$C,3,0)) | F23: =IF(B23="","",C23*E23) | H23: =IF(I23="","",16) | I23: {=IFERROR(INDEX(Заказы!$A$3:$A$29,SMALL(IF(Заказы!$C$3:$C$29>0,ROW(Заказы!$C$3:$C$29)-ROW(C$3)+1),16)),"")} | J23: =IF(I23="","",INDEX(Заказы!$C$3:$C$29,MATCH(I23,Заказы!$A$3:$A$29,0))) | K23: =IF(I23="","",VLOOKUP(I23,Каталог!$A:$C,2,0)) | L23: =IF(I23="","",VLOOKUP(I23,Каталог!$A:$C,3,0)) | M23: =IF(I23="","",J23*L23)
A24: =IF(B24="","",17) | B24: {=IFERROR(INDEX(Заказы!$A$3:$A$29,SMALL(IF(Заказы!$B$3:$B$29>0,ROW(Заказы!$B$3:$B$29)-ROW(B$3)+1),17)),"")} | C24: =IF(B24="","",INDEX(Заказы!$B$3:$B$29,MATCH(B24,Заказы!$A$3:$A$29,0))) | D24: =IF(B24="","",VLOOKUP(B24,Каталог!$A:$C,2,0)) | E24: =IF(B24="","",VLOOKUP(B24,Каталог!$A:$C,3,0)) | F24: =IF(B24="","",C24*E24) | H24: =IF(I24="","",17) | I24: {=IFERROR(INDEX(Заказы!$A$3:$A$29,SMALL(IF(Заказы!$C$3:$C$29>0,ROW(Заказы!$C$3:$C$29)-ROW(C$3)+1),17)),"")} | J24: =IF(I24="","",INDEX(Заказы!$C$3:$C$29,MATCH(I24,Заказы!$A$3:$A$29,0))) | K24: =IF(I24="","",VLOOKUP(I24,Каталог!$A:$C,2,0)) | L24: =IF(I24="","",VLOOKUP(I24,Каталог!$A:$C,3,0)) | M24: =IF(I24="","",J24*L24)
A25: =IF(B25="","",18) | B25: {=IFERROR(INDEX(Заказы!$A$3:$A$29,SMALL(IF(Заказы!$B$3:$B$29>0,ROW(Заказы!$B$3:$B$29)-ROW(B$3)+1),18)),"")} | C25: =IF(B25="","",INDEX(Заказы!$B$3:$B$29,MATCH(B25,Заказы!$A$3:$A$29,0))) | D25: =IF(B25="","",VLOOKUP(B25,Каталог!$A:$C,2,0)) | E25: =IF(B25="","",VLOOKUP(B25,Каталог!$A:$C,3,0)) | F25: =IF(B25="","",C25*E25) | H25: =IF(I25="","",18) | I25: {=IFERROR(INDEX(Заказы!$A$3:$A$29,SMALL(IF(Заказы!$C$3:$C$29>0,ROW(Заказы!$C$3:$C$29)-ROW(C$3)+1),18)),"")} | J25: =IF(I25="","",INDEX(Заказы!$C$3:$C$29,MATCH(I25,Заказы!$A$3:$A$29,0))) | K25: =IF(I25="","",VLOOKUP(I25,Каталог!$A:$C,2,0)) | L25: =IF(I25="","",VLOOKUP(I25,Каталог!$A:$C,3,0)) | M25: =IF(I25="","",J25*L25)
A26: =IF(B26="","",19) | B26: {=IFERROR(INDEX(Заказы!$A$3:$A$29,SMALL(IF(Заказы!$B$3:$B$29>0,ROW(Заказы!$B$3:$B$29)-ROW(B$3)+1),19)),"")} | C26: =IF(B26="","",INDEX(Заказы!$B$3:$B$29,MATCH(B26,Заказы!$A$3:$A$29,0))) | D26: =IF(B26="","",VLOOKUP(B26,Каталог!$A:$C,2,0)) | E26: =IF(B26="","",VLOOKUP(B26,Каталог!$A:$C,3,0)) | F26: =IF(B26="","",C26*E26) | H26: =IF(I26="","",19) | I26: {=IFERROR(INDEX(Заказы!$A$3:$A$29,SMALL(IF(Заказы!$C$3:$C$29>0,ROW(Заказы!$C$3:$C$29)-ROW(C$3)+1),19)),"")} | J26: =IF(I26="","",INDEX(Заказы!$C$3:$C$29,MATCH(I26,Заказы!$A$3:$A$29,0))) | K26: =IF(I26="","",VLOOKUP(I26,Каталог!$A:$C,2,0)) | L26: =IF(I26="","",VLOOKUP(I26,Каталог!$A:$C,3,0)) | M26: =IF(I26="","",J26*L26)
A27: =IF(B27="","",20) | B27: {=IFERROR(INDEX(Заказы!$A$3:$A$29,SMALL(IF(Заказы!$B$3:$B$29>0,ROW(Заказы!$B$3:$B$29)-ROW(B$3)+1),20)),"")} | C27: =IF(B27="","",INDEX(Заказы!$B$3:$B$29,MATCH(B27,Заказы!$A$3:$A$29,0))) | D27: =IF(B27="","",VLOOKUP(B27,Каталог!$A:$C,2,0)) | E27: =IF(B27="","",VLOOKUP(B27,Каталог!$A:$C,3,0)) | F27: =IF(B27="","",C27*E27) | H27: =IF(I27="","",20) | I27: {=IFERROR(INDEX(Заказы!$A$3:$A$29,SMALL(IF(Заказы!$C$3:$C$29>0,ROW(Заказы!$C$3:$C$29)-ROW(C$3)+1),20)),"")} | J27: =IF(I27="","",INDEX(Заказы!$C$3:$C$29,MATCH(I27,Заказы!$A$3:$A$29,0))) | K27: =IF(I27="","",VLOOKUP(I27,Каталог!$A:$C,2,0)) | L27: =IF(I27="","",VLOOKUP(I27,Каталог!$A:$C,3,0)) | M27: =IF(I27="","",J27*L27)
A28: =IF(B28="","",21) | B28: {=IFERROR(INDEX(Заказы!$A$3:$A$29,SMALL(IF(Заказы!$B$3:$B$29>0,ROW(Заказы!$B$3:$B$29)-ROW(B$3)+1),21)),"")} | C28: =IF(B28="","",INDEX(Заказы!$B$3:$B$29,MATCH(B28,Заказы!$A$3:$A$29,0))) | D28: =IF(B28="","",VLOOKUP(B28,Каталог!$A:$C,2,0)) | E28: =IF(B28="","",VLOOKUP(B28,Каталог!$A:$C,3,0)) | F28: =IF(B28="","",C28*E28) | H28: =IF(I28="","",21) | I28: {=IFERROR(INDEX(Заказы!$A$3:$A$29,SMALL(IF(Заказы!$C$3:$C$29>0,ROW(Заказы!$C$3:$C$29)-ROW(C$3)+1),21)),"")} | J28: =IF(I28="","",INDEX(Заказы!$C$3:$C$29,MATCH(I28,Заказы!$A$3:$A$29,0))) | K28: =IF(I28="","",VLOOKUP(I28,Каталог!$A:$C,2,0)) | L28: =IF(I28="","",VLOOKUP(I28,Каталог!$A:$C,3,0)) | M28: =IF(I28="","",J28*L28)
A29: =IF(B29="","",22) | B29: {=IFERROR(INDEX(Заказы!$A$3:$A$29,SMALL(IF(Заказы!$B$3:$B$29>0,ROW(Заказы!$B$3:$B$29)-ROW(B$3)+1),22)),"")} | C29: =IF(B29="","",INDEX(Заказы!$B$3:$B$29,MATCH(B29,Заказы!$A$3:$A$29,0))) | D29: =IF(B29="","",VLOOKUP(B29,Каталог!$A:$C,2,0)) | E29: =IF(B29="","",VLOOKUP(B29,Каталог!$A:$C,3,0)) | F29: =IF(B29="","",C29*E29) | H29: =IF(I29="","",22) | I29: {=IFERROR(INDEX(Заказы!$A$3:$A$29,SMALL(IF(Заказы!$C$3:$C$29>0,ROW(Заказы!$C$3:$C$29)-ROW(C$3)+1),22)),"")} | J29: =IF(I29="","",INDEX(Заказы!$C$3:$C$29,MATCH(I29,Заказы!$A$3:$A$29,0))) | K29: =IF(I29="","",VLOOKUP(I29,Каталог!$A:$C,2,0)) | L29: =IF(I29="","",VLOOKUP(I29,Каталог!$A:$C,3,0)) | M29: =IF(I29="","",J29*L29)
A30: =IF(B30="","",23) | B30: {=IFERROR(INDEX(Заказы!$A$3:$A$29,SMALL(IF(Заказы!$B$3:$B$29>0,ROW(Заказы!$B$3:$B$29)-ROW(B$3)+1),23)),"")} | C30: =IF(B30="","",INDEX(Заказы!$B$3:$B$29,MATCH(B30,Заказы!$A$3:$A$29,0))) | D30: =IF(B30="","",VLOOKUP(B30,Каталог!$A:$C,2,0)) | E30: =IF(B30="","",VLOOKUP(B30,Каталог!$A:$C,3,0)) | F30: =IF(B30="","",C30*E30) | H30: =IF(I30="","",23) | I30: {=IFERROR(INDEX(Заказы!$A$3:$A$29,SMALL(IF(Заказы!$C$3:$C$29>0,ROW(Заказы!$C$3:$C$29)-ROW(C$3)+1),23)),"")} | J30: =IF(I30="","",INDEX(Заказы!$C$3:$C$29,MATCH(I30,Заказы!$A$3:$A$29,0))) | K30: =IF(I30="","",VLOOKUP(I30,Каталог!$A:$C,2,0)) | L30: =IF(I30="","",VLOOKUP(I30,Каталог!$A:$C,3,0)) | M30: =IF(I30="","",J30*L30)
A31: =IF(B31="","",24) | B31: {=IFERROR(INDEX(Заказы!$A$3:$A$29,SMALL(IF(Заказы!$B$3:$B$29>0,ROW(Заказы!$B$3:$B$29)-ROW(B$3)+1),24)),"")} | C31: =IF(B31="","",INDEX(Заказы!$B$3:$B$29,MATCH(B31,Заказы!$A$3:$A$29,0))) | D31: =IF(B31="","",VLOOKUP(B31,Каталог!$A:$C,2,0)) | E31: =IF(B31="","",VLOOKUP(B31,Каталог!$A:$C,3,0)) | F31: =IF(B31="","",C31*E31) | H31: =IF(I31="","",24) | I31: {=IFERROR(INDEX(Заказы!$A$3:$A$29,SMALL(IF(Заказы!$C$3:$C$29>0,ROW(Заказы!$C$3:$C$29)-ROW(C$3)+1),24)),"")} | J31: =IF(I31="","",INDEX(Заказы!$C$3:$C$29,MATCH(I31,Заказы!$A$3:$A$29,0))) | K31: =IF(I31="","",VLOOKUP(I31,Каталог!$A:$C,2,0)) | L31: =IF(I31="","",VLOOKUP(I31,Каталог!$A:$C,3,0)) | M31: =IF(I31="","",J31*L31)
A32: =IF(B32="","",25) | B32: {=IFERROR(INDEX(Заказы!$A$3:$A$29,SMALL(IF(Заказы!$B$3:$B$29>0,ROW(Заказы!$B$3:$B$29)-ROW(B$3)+1),25)),"")} | C32: =IF(B32="","",INDEX(Заказы!$B$3:$B$29,MATCH(B32,Заказы!$A$3:$A$29,0))) | D32: =IF(B32="","",VLOOKUP(B32,Каталог!$A:$C,2,0)) | E32: =IF(B32="","",VLOOKUP(B32,Каталог!$A:$C,3,0)) | F32: =IF(B32="","",C32*E32) | H32: =IF(I32="","",25) | I32: {=IFERROR(INDEX(Заказы!$A$3:$A$29,SMALL(IF(Заказы!$C$3:$C$29>0,ROW(Заказы!$C$3:$C$29)-ROW(C$3)+1),25)),"")} | J32: =IF(I32="","",INDEX(Заказы!$C$3:$C$29,MATCH(I32,Заказы!$A$3:$A$29,0))) | K32: =IF(I32="","",VLOOKUP(I32,Каталог!$A:$C,2,0)) | L32: =IF(I32="","",VLOOKUP(I32,Каталог!$A:$C,3,0)) | M32: =IF(I32="","",J32*L32)
A33: =IF(B33="","",26) | B33: {=IFERROR(INDEX(Заказы!$A$3:$A$29,SMALL(IF(Заказы!$B$3:$B$29>0,ROW(Заказы!$B$3:$B$29)-ROW(B$3)+1),26)),"")} | C33: =IF(B33="","",INDEX(Заказы!$B$3:$B$29,MATCH(B33,Заказы!$A$3:$A$29,0))) | D33: =IF(B33="","",VLOOKUP(B33,Каталог!$A:$C,2,0)) | E33: =IF(B33="","",VLOOKUP(B33,Каталог!$A:$C,3,0)) | F33: =IF(B33="","",C33*E33) | H33: =IF(I33="","",26) | I33: {=IFERROR(INDEX(Заказы!$A$3:$A$29,SMALL(IF(Заказы!$C$3:$C$29>0,ROW(Заказы!$C$3:$C$29)-ROW(C$3)+1),26)),"")} | J33: =IF(I33="","",INDEX(Заказы!$C$3:$C$29,MATCH(I33,Заказы!$A$3:$A$29,0))) | K33: =IF(I33="","",VLOOKUP(I33,Каталог!$A:$C,2,0)) | L33: =IF(I33="","",VLOOKUP(I33,Каталог!$A:$C,3,0)) | M33: =IF(I33="","",J33*L33)
A34: =IF(B34="","",27) | B34: {=IFERROR(INDEX(Заказы!$A$3:$A$29,SMALL(IF(Заказы!$B$3:$B$29>0,ROW(Заказы!$B$3:$B$29)-ROW(B$3)+1),27)),"")} | C34: =IF(B34="","",INDEX(Заказы!$B$3:$B$29,MATCH(B34,Заказы!$A$3:$A$29,0))) | D34: =IF(B34="","",VLOOKUP(B34,Каталог!$A:$C,2,0)) | E34: =IF(B34="","",VLOOKUP(B34,Каталог!$A:$C,3,0)) | F34: =IF(B34="","",C34*E34) | H34: =IF(I34="","",27) | I34: {=IFERROR(INDEX(Заказы!$A$3:$A$29,SMALL(IF(Заказы!$C$3:$C$29>0,ROW(Заказы!$C$3:$C$29)-ROW(C$3)+1),27)),"")} | J34: =IF(I34="","",INDEX(Заказы!$C$3:$C$29,MATCH(I34,Заказы!$A$3:$A$29,0))) | K34: =IF(I34="","",VLOOKUP(I34,Каталог!$A:$C,2,0)) | L34: =IF(I34="","",VLOOKUP(I34,Каталог!$A:$C,3,0)) | M34: =IF(I34="","",J34*L34)
A36: =IF(COUNTIF(Заказы!$B$3:$B$29,">0")=0,"","Итого:") -> Итого: | E36: =IF(COUNTIF(Заказы!$B$3:$B$29,">0")=0,"",SUM(F8:F34)) -> 12530 | H36: =IF(COUNTIF(Заказы!$C$3:$C$29,">0")=0,"","Итого:") -> Итого: | L36: =IF(COUNTIF(Заказы!$C$3:$C$29,">0")=0,"",SUM(M8:M34)) -> 2070
A38: =IF(COUNTIF(Заказы!$B$3:$B$29,">0")=0,"","Подпись отправителя: __________________") -> Подпись отправителя: __________________ | H38: =IF(COUNTIF(Заказы!$C$3:$C$29,">0")=0,"","Подпись отправителя: __________________") -> Подпись отправителя: __________________
A39: =IF(COUNTIF(Заказы!$B$3:$B$29,">0")=0,"","Подпись получателя: ___________________") -> Подпись получателя: ___________________ | H39: =IF(COUNTIF(Заказы!$C$3:$C$29,">0")=0,"","Подпись получателя: ___________________") -> Подпись получателя: ___________________
A41: =IF(COUNTIF(Заказы!$D$3:$D$29,">0")=0,"","НАКЛАДНАЯ") -> НАКЛАДНАЯ | H41: =IF(COUNTIF(Заказы!$E$3:$E$29,">0")=0,"","НАКЛАДНАЯ") -> НАКЛАДНАЯ
A42: =IF(COUNTIF(Заказы!$D$3:$D$29,">0")=0,"","Отправитель: Brown кондитерский цех") -> Отправитель: Brown кондитерский цех | H42: =IF(COUNTIF(Заказы!$E$3:$E$29,">0")=0,"","Отправитель: Brown кондитерский цех") -> Отправитель: Brown кондитерский цех
A43: =IF(COUNTIF(Заказы!$D$3:$D$29,">0")=0,"","Получатель: "&Заказы!D$2) -> Получатель: Ашимова | H43: =IF(COUNTIF(Заказы!$E$3:$E$29,">0")=0,"","Получатель: "&Заказы!E$2) -> Получатель: Гагарина
A44: =IF(COUNTIF(Заказы!$D$3:$D$29,">0")=0,"","Накладная от: "&TEXT(Заказы!$B$1,"dd.mm.yyyy")) -> Накладная от: 22.09.2026 | H44: =IF(COUNTIF(Заказы!$E$3:$E$29,">0")=0,"","Накладная от: "&TEXT(Заказы!$B$1,"dd.mm.yyyy")) -> Накладная от: 22.09.2026
A46: =IF(COUNTIF(Заказы!$D$3:$D$29,">0")=0,"","№") -> № | B46: =IF(COUNTIF(Заказы!$D$3:$D$29,">0")=0,"","Наименование") -> Наименование | C46: =IF(COUNTIF(Заказы!$D$3:$D$29,">0")=0,"","Кол.") -> Кол. | D46: =IF(COUNTIF(Заказы!$D$3:$D$29,">0")=0,"","Ед.") -> Ед. | E46: =IF(COUNTIF(Заказы!$D$3:$D$29,">0")=0,"","Цена") -> Цена | F46: =IF(COUNTIF(Заказы!$D$3:$D$29,">0")=0,"","Сумма") -> Сумма | H46: =IF(COUNTIF(Заказы!$E$3:$E$29,">0")=0,"","№") -> № | I46: =IF(COUNTIF(Заказы!$E$3:$E$29,">0")=0,"","Наименование") -> Наименование | J46: =IF(COUNTIF(Заказы!$E$3:$E$29,">0")=0,"","Кол.") -> Кол. | K46: =IF(COUNTIF(Заказы!$E$3:$E$29,">0")=0,"","Ед.") -> Ед. | L46: =IF(COUNTIF(Заказы!$E$3:$E$29,">0")=0,"","Цена") -> Цена | M46: =IF(COUNTIF(Заказы!$E$3:$E$29,">0")=0,"","Сумма") -> Сумма
...
